<?xml version="1.0" encoding="UTF-8"?>
<robot name="labrob">
  <link name="base_link">
    <visual>
      <origin xyz="0 0 0" rpy="0 0 0"/>
      <geometry>
        <box size="1 0.5 0.25" />
      </geometry>
      <meterial name="Cyan">
        <color rgba="0 1.0 1.0 1.0" />
      </meterial>
    </visual>
  </link>

  <link name="f_r_wheel">
    <visual>
      <origin xyz="0 0 0" rpy="1.570795 0 0"/>
      <geometry>
        <cylinder length="0.1" radius="0.2" />
      </geometry>
      <material name="black">
        <color rgba="0.05 0.05 0.05 1" />
      </material>
    </visual>
  </link>
  <joint name="joint_f_r_wheel" type="continuous">
    <parent link="base_link"/>
    <child link="f_r_wheel"/>
    <origin xyz="0.25 -0.30 0" rpy="0 0 0" />
    <axis xyz="0 1 0" rpy="0 0 0" />
  </joint>

  <link name="f_l_wheel">
      <visual>
            <origin xyz="0 0 0" rpy="1.570795 0 0"/>
            <geometry>
              <cylinder length="0.1" radius="0.2" />
            </geometry>
            <material name="black">
              <color rgba="0.05 0.05 0.05 1" />
            </material>
      </visual>
  </link>
  <joint name="joint_f_l_wheel" type="continuous">
    <parent link="base_link"/>
    <child link="f_l_wheel"/>
    <origin xyz="0.25 0.30 0" rpy="0 0 0" />
    <axis xyz="0 1 0" rpy="0 0 0" />
  </joint>

  <link name="b_r_wheel">
      <visual>
            <origin xyz="0 0 0" rpy="1.570795 0 0"/>
            <geometry>
              <cylinder length="0.1" radius="0.2" />
            </geometry>
            <material name="black">
              <color rgba="0.05 0.05 0.05 1" />
            </material>
      </visual>
  </link>
  <joint name="joint_b_r_wheel" type="continuous">
    <parent link="base_link"/>
    <child link="b_r_wheel"/>
    <origin xyz="-0.25 -0.30 0" rpy="0 0 0" />
    <axis xyz="0 1 0" rpy="0 0 0" />
  </joint>

  <link name="b_l_wheel">
      <visual>
            <origin xyz="0 0 0" rpy="1.570795 0 0"/>
            <geometry>
              <cylinder length="0.1" radius="0.2" />
            </geometry>
            <material name="black">
              <color rgba="0.05 0.05 0.05 1" />
            </material>
      </visual>
  </link>
  <joint name="joint_b_l_wheel" type="continuous">
    <parent link="base_link"/>
    <child link="b_l_wheel"/>
    <origin xyz="-0.25 0.30 0" rpy="0 0 0" />
    <axis xyz="0 1 0" rpy="0 0 0" />
  </joint>


</robot>
