<?xml version="1.0" ?>
<!-- =================================================================================== -->
<!-- |    This document was autogenerated by xacro from /home/taiwanet/catkin_ws/src/labrob/labrob_description/urdf/ocare.urdf.xacro | -->
<!-- |    EDITING THIS FILE BY HAND IS NOT RECOMMENDED                                 | -->
<!-- =================================================================================== -->
<robot name="ocare" xmlns:xacro="http://www.ros.org/wiki/xacro">
  <material name="Black">
    <color rgba="0.0 0.0 0.0 1.0"/>
  </material>
  <material name="Blue">
    <color rgba="0.0 0.0 0.8 1.0"/>
  </material>
  <material name="Green">
    <color rgba="0.0 0.8 0.0 1.0"/>
  </material>
  <material name="Gray">
    <color rgba="0.7 0.7 0.7 1.0"/>
  </material>
  <material name="DarkGray">
    <color rgba="0.3 0.3 0.3 1.0"/>
  </material>
  <material name="Red">
    <color rgba="0.8 0.0 0.0 1.0"/>
  </material>
  <material name="White">
    <color rgba="1.0 1.0 1.0 1.0"/>
  </material>
  <material name="Yellow">
    <color rgba="0.8 0.8 0.0 1.0"/>
  </material>
  <!-- in kg-->
  <!-- in kg-->
  <!-- BASE-FOOTPRINT -->
  <!-- base_footprint is a fictitious link(frame) that is on the ground right below base_link origin -->
  <!--link name="base_footprint">
    <inertial>
      <mass value="0.0001" />
      <origin xyz="0 0 0" />
      <inertia ixx="0.0001" ixy="0.0" ixz="0.0"
          iyy="0.0001" iyz="0.0" 
          izz="0.0001" />
    </inertial>
    <visual>
        <origin xyz="0 0 0" rpy="0 0 0" />
        <geometry>
            <box size="0.001 0.001 0.001" />
        </geometry>
    </visual>
  </link>
  
  <joint name="base_footprint_joint" type="fixed">
	<origin xyz="0 0 ${wheel_radius - base_z_origin_to_wheel_origin}" rpy="0 0 0" />
    <parent link="base_footprint"/>
    <child link="base_link" />
  </joint>
  
  <gazebo reference="base_footprint">
    <turnGravityOff>false</turnGravityOff>
  </gazebo-->
  <!-- BASE-LINK -->
  <!--Actual body/chassis of the robot-->
  <link name="base_link">
    <inertial>
      <mass value="15"/>
      <origin xyz="0 0 0"/>
      <inertia ixx="0.3215" ixy="0" ixz="0" iyy="0.3215" iyz="0" izz="0.243"/>
    </inertial>
    <visual name="visual">
      <origin rpy="0 0 0 " xyz="0 0 -0.14"/>
      <geometry>
        <cylinder length="0.4" radius="0.18"/>
      </geometry>
      <material name="Gray"/>
    </visual>
    <!--visual name="caster_visual">
		<origin xyz="-0.15 0 0" rpy="0 0 0 " />
          <geometry>
            <sphere>
              <radius>.05</radius>
            </sphere>
          </geometry>
      <material name="Yellow" />
    </visual-->
    <collision>
      <origin rpy="0 0 0 " xyz="0 0 0.2"/>
      <geometry>
        <cylinder length="0.4" radius="0.18"/>
      </geometry>
    </collision>
  </link>
  <gazebo reference="base_link">
    <material>Gazebo/Yellow</material>
    <turnGravityOff>false</turnGravityOff>
  </gazebo>
  <!--LEFT-ARM-BASE-->
  <link name="left_arm_base_link">
    <inertial>
      <mass value="0.2"/>
      <origin rpy="0 0 0 " xyz="0.0 0.0 0.05"/>
      <inertia ixx="0.000173333333333" ixy="0" ixz="0" iyy="0.000208333333333" iyz="0" izz="0.000208333333333"/>
    </inertial>
    <visual name="visual">
      <origin rpy="0 0 0 " xyz="0.0 0.0 0.05"/>
      <geometry>
        <box size="0.05 0.02 0.1"/>
      </geometry>
      <material name="Green"/>
    </visual>
    <collision>
      <origin rpy="0 0 0 " xyz="-0.025 -0.01 0.05"/>
      <geometry>
        <box size="0.05 0.02 0.1"/>
      </geometry>
    </collision>
  </link>
  <gazebo reference="left_arm_base_link">
    <material>Gazebo/Grey</material>
    <turnGravityOff>false</turnGravityOff>
  </gazebo>
  <joint name="left_arm_base_link_joint" type="prismatic">
    <parent link="base_link"/>
    <child link="left_arm_base_link"/>
    <origin rpy="-1.57079632679 0 0" xyz="0.0 0.05 0.0"/>
    <axis xyz="0 0 1"/>
    <limit effort="100" lower="0" upper="0.15" velocity="100"/>
    <joint_properties damping="0.0" friction="0.0"/>
  </joint>
  <transmission name="left_arm_base_link_tran">
    <type>transmission_interface/SimpleTransmission</type>
    <joint name="left_arm_base_link_joint">
      <hardwareInterface>EffortJointInterface</hardwareInterface>
    </joint>
    <actuator name="left_arm_base_link_joint_actu">
      <hardwareInterface>EffortJointInterface</hardwareInterface>
      <mechanicalReduction>1</mechanicalReduction>
    </actuator>
  </transmission>
  <!--fb : front, back ; lr: left, right -->
  <link name="base_right_wheel">
    <visual>
      <origin rpy="-1.57079632679 0 0" xyz="0 0 0"/>
      <geometry>
        <cylinder length="0.01" radius="0.06"/>
      </geometry>
      <material name="DarkGray"/>
    </visual>
    <collision>
      <origin rpy="-1.57079632679 0 0" xyz="0 0 0"/>
      <geometry>
        <cylinder length="0.01" radius="0.06"/>
      </geometry>
    </collision>
    <inertial>
      <mass value="2.5"/>
      <origin xyz="0 0 0"/>
      <inertia ixx="0.00227083333333" ixy="0" ixz="0" iyy="0.00227083333333" iyz="0" izz="0.0045"/>
    </inertial>
  </link>
  <gazebo reference="base_right_wheel">
    <mu1 value="1.0"/>
    <mu2 value="1.0"/>
    <kp value="10000000.0"/>
    <kd value="1.0"/>
    <fdir1 value="1 0 0"/>
    <material>Gazebo/Grey</material>
    <turnGravityOff>false</turnGravityOff>
  </gazebo>
  <joint name="base_right_wheel_joint" type="continuous">
    <parent link="base_link"/>
    <child link="base_right_wheel"/>
    <origin rpy="0 0 0" xyz="0 -0.165 -0.34"/>
    <axis rpy="0 0 0" xyz="0 1 0"/>
    <limit effort="100" velocity="100"/>
    <joint_properties damping="0.0" friction="0.0"/>
  </joint>
  <!-- Transmission is important to link the joints and the controller -->
  <transmission name="base_right_wheel_joint_trans">
    <type>transmission_interface/SimpleTransmission</type>
    <joint name="base_right_wheel_joint">
      <hardwareInterface>EffortJointInterface</hardwareInterface>
    </joint>
    <actuator name="base_right_wheel_joint_motor">
      <hardwareInterface>EffortJointInterface</hardwareInterface>
      <mechanicalReduction>1</mechanicalReduction>
    </actuator>
  </transmission>
  <!--fb : front, back ; lr: left, right -->
  <link name="base_left_wheel">
    <visual>
      <origin rpy="-1.57079632679 0 0" xyz="0 0 0"/>
      <geometry>
        <cylinder length="0.01" radius="0.06"/>
      </geometry>
      <material name="DarkGray"/>
    </visual>
    <collision>
      <origin rpy="-1.57079632679 0 0" xyz="0 0 0"/>
      <geometry>
        <cylinder length="0.01" radius="0.06"/>
      </geometry>
    </collision>
    <inertial>
      <mass value="2.5"/>
      <origin xyz="0 0 0"/>
      <inertia ixx="0.00227083333333" ixy="0" ixz="0" iyy="0.00227083333333" iyz="0" izz="0.0045"/>
    </inertial>
  </link>
  <gazebo reference="base_left_wheel">
    <mu1 value="1.0"/>
    <mu2 value="1.0"/>
    <kp value="10000000.0"/>
    <kd value="1.0"/>
    <fdir1 value="1 0 0"/>
    <material>Gazebo/Grey</material>
    <turnGravityOff>false</turnGravityOff>
  </gazebo>
  <joint name="base_left_wheel_joint" type="continuous">
    <parent link="base_link"/>
    <child link="base_left_wheel"/>
    <origin rpy="0 0 0" xyz="0 0.165 -0.34"/>
    <axis rpy="0 0 0" xyz="0 1 0"/>
    <limit effort="100" velocity="100"/>
    <joint_properties damping="0.0" friction="0.0"/>
  </joint>
  <!-- Transmission is important to link the joints and the controller -->
  <transmission name="base_left_wheel_joint_trans">
    <type>transmission_interface/SimpleTransmission</type>
    <joint name="base_left_wheel_joint">
      <hardwareInterface>EffortJointInterface</hardwareInterface>
    </joint>
    <actuator name="base_left_wheel_joint_motor">
      <hardwareInterface>EffortJointInterface</hardwareInterface>
      <mechanicalReduction>1</mechanicalReduction>
    </actuator>
  </transmission>
  .
  
   
  <link name="base_idler_wheel">
    <visual>
      <origin rpy="0 0 0" xyz="0 0 0"/>
      <geometry>
        <sphere radius=".06"/>
      </geometry>
      <material name="DarkGray"/>
    </visual>
    <collision>
      <origin rpy="0 0 0" xyz="0 0 0"/>
      <geometry>
        <sphere radius=".06"/>
      </geometry>
    </collision>
    <inertial>
      <mass value="2.5"/>
      <origin xyz="0 0 0"/>
      <inertia ixx="0.00227083333333" ixy="0" ixz="0" iyy="0.00227083333333" iyz="0" izz="0.00227083333333"/>
    </inertial>
  </link>
  <gazebo reference="base_idler_wheel">
    <mu1 value="0.0"/>
    <mu2 value="0.0"/>
    <kp value="10000000.0"/>
    <kd value="1.0"/>
    <fdir1 value="1 0 0"/>
    <material>Gazebo/Grey</material>
    <turnGravityOff>false</turnGravityOff>
  </gazebo>
  <joint name="base_idler_wheel_joint" type="continuous">
    <parent link="base_link"/>
    <child link="base_idler_wheel"/>
    <origin rpy="0 0 0" xyz="-0.21 0 -0.34"/>
    <axis rpy="0 0 0" xyz="0 1 0"/>
    <limit effort="100" velocity="100"/>
    <joint_properties damping="0.0" friction="0.0"/>
  </joint>
  <gazebo>
    <plugin filename="libgazebo_ros_diff_drive.so" name="differential_drive_controller">
      <alwaysOn>true</alwaysOn>
      <updateRate>50</updateRate>
      <leftJoint>front_left_wheel_joint</leftJoint>
      <rightJoint>front_right_wheel_joint</rightJoint>
      <wheelSeparation>0.33</wheelSeparation>
      <wheelDiameter>0.125</wheelDiameter>
      <torque>20</torque>
      <commandTopic>cmd_vel</commandTopic>
      <odometryTopic>odom</odometryTopic>
      <odometryFrame>odom</odometryFrame>
      <robotBaseFrame>base_footprint</robotBaseFrame>
      <publishWheelTF>true</publishWheelTF>
      <publishWheelJointState>true</publishWheelJointState>
    </plugin>
  </gazebo>
</robot>

